Workbook

Sheet Billetes_Brutos
A1: id_billete | B1: id_cliente | C1: nombre_cliente | D1: correo | E1: fecha_nacimiento | F1: tipo_cliente | G1: estacion_salida | H1: estacion_llegada | I1: fecha_viaje | J1: clase | K1: estado | L1: precio | M1: fecha_compra | N1: Duplicado | O1: Clase_Uniforme | P1: Correo_Estado | Q1: Precio_Estado
A2: 1047 | B2: 22 | C2: Santiago Sanchez | D2: santiago.sanchez22@correo.co | E2: 11/01/1974 | F2: Ocasional | G2: Cartagena | H2: Bucaramanga | I2: 13/03/2026 | J2: segunda | K2: Pagado | L2: 47800 | M2: 19/12/2025 | N2: =IF(COUNTIF($A$2:A2,A2)>1,"Si","No") -> No | O2: =VLOOKUP(J2,Referencias!$A$2:$B$7,2,FALSE()) -> Segunda | P2: =IF(D2="","Faltante","OK") -> OK | Q2: =IF(L2="","Faltante","OK") -> OK
A3: 1079 | B3: 45 | C3: Gabriela Perez | D3: gabriela.perez45@correo.co | E3: 21/03/1992 | F3: Abonado | G3: Manizales | H3: Pereira | I3: 13/03/2026 | J3: 1era | K3: Pagado | L3: 167300 | M3: 31/12/2025 | N3: =IF(COUNTIF($A$2:A3,A3)>1,"Si","No") -> No | O3: =VLOOKUP(J3,Referencias!$A$2:$B$7,2,FALSE()) -> Primera | P3: =IF(D3="","Faltante","OK") -> OK | Q3: =IF(L3="","Faltante","OK") -> OK
A4: 1016 | B4: 60 | C4: Mateo Sanchez | D4: mateo.sanchez60@correo.co | E4: 14/10/1963 | F4: Abonado | G4: Santa Marta | H4: Bogota Central | I4: 24/01/2026 | J4: 1ra | K4: Pagado | L4: 103800 | M4: 11/02/2026 | N4: =IF(COUNTIF($A$2:A4,A4)>1,"Si","No") -> No | O4: =VLOOKUP(J4,Referencias!$A$2:$B$7,2,FALSE()) -> Primera | P4: =IF(D4="","Faltante","OK") -> OK | Q4: =IF(L4="","Faltante","OK") -> OK
A5: 1057 | B5: 29 | C5: Mateo Torres | E5: 01/12/1983 | F5: Ocasional | G5: Bogota Central | H5: Medellin | I5: 28/02/2026 | J5: 2nda | K5: Anulado | L5: 306500 | M5: 15/05/2026 | N5: =IF(COUNTIF($A$2:A5,A5)>1,"Si","No") -> No | O5: =VLOOKUP(J5,Referencias!$A$2:$B$7,2,FALSE()) -> Segunda | P5: =IF(D5="","Faltante","OK") -> Faltante | Q5: =IF(L5="","Faltante","OK") -> OK
A6: 1076 | B6: 36 | C6: Daniela Rodriguez | D6: daniela.rodriguez36@correo.co | F6: Abonado | G6: Manizales | H6: Bucaramanga | I6: 22/06/2026 | J6: 2nda | K6: Pagado | L6: 271200 | M6: 04/02/2026 | N6: =IF(COUNTIF($A$2:A6,A6)>1,"Si","No") -> No | O6: =VLOOKUP(J6,Referencias!$A$2:$B$7,2,FALSE()) -> Segunda | P6: =IF(D6="","Faltante","OK") -> OK | Q6: =IF(L6="","Faltante","OK") -> OK
A7: 1022 | B7: 24 | C7: Sofia Martinez | D7: sofia.martinez24@correo.co | E7: 20/02/1982 | F7: Abonado | G7: Santa Marta | H7: Cartagena | I7: 19/06/2026 | J7: 1era | K7: Reembolsado | L7: 76700 | M7: 28/11/2025 | N7: =IF(COUNTIF($A$2:A7,A7)>1,"Si","No") -> No | O7: =VLOOKUP(J7,Referencias!$A$2:$B$7,2,FALSE()) -> Primera | P7: =IF(D7="","Faltante","OK") -> OK | Q7: =IF(L7="","Faltante","OK") -> OK
A8: 1065 | B8: 56 | C8: Sebastian Hernandez | D8: sebastian.hernandez56@correo.co | E8: 08/11/1991 | F8: Abonado | G8: Bucaramanga | H8: Manizales | I8: 30/06/2026 | J8: 2da | K8: Pagado | L8: 270700 | M8: 09/12/2025 | N8: =IF(COUNTIF($A$2:A8,A8)>1,"Si","No") -> No | O8: =VLOOKUP(J8,Referencias!$A$2:$B$7,2,FALSE()) -> Segunda | P8: =IF(D8="","Faltante","OK") -> OK | Q8: =IF(L8="","Faltante","OK") -> OK
A9: 1004 | B9: 24 | C9: Daniela Hernandez | D9: daniela.hernandez24@correo.co | E9: 28/05/1961 | F9: Abonado | G9: Santa Marta | H9: Barranquilla | I9: 11/02/2026 | J9: 2da | K9: Pagado | L9: 221000 | M9: 23/03/2026 | N9: =IF(COUNTIF($A$2:A9,A9)>1,"Si","No") -> No | O9: =VLOOKUP(J9,Referencias!$A$2:$B$7,2,FALSE()) -> Segunda | P9: =IF(D9="","Faltante","OK") -> OK | Q9: =IF(L9="","Faltante","OK") -> OK
A10: 1115 | B10: 51 | C10: Mateo Gonzalez | D10: mateo.gonzalez51@correo.co | E10: 19/04/1964 | F10: Ocasional | G10: Cali | H10: Bogota Central | I10: 01/04/2026 | J10: segunda | K10: Pagado | L10: 273400 | M10: 25/04/2026 | N10: =IF(COUNTIF($A$2:A10,A10)>1,"Si","No") -> No | O10: =VLOOKUP(J10,Referencias!$A$2:$B$7,2,FALSE()) -> Segunda | P10: =IF(D10="","Faltante","OK") -> OK | Q10: =IF(L10="","Faltante","OK") -> OK
A11: 1064 | B11: 47 | C11: Sofia Torres | D11: sofia.torres47@correo.co | E11: 01/05/1968 | F11: Ocasional | G11: Santa Marta | H11: Manizales | I11: 30/03/2026 | J11: primera | K11: Pagado | L11: 170200 | M11: 22/01/2026 | N11: =IF(COUNTIF($A$2:A11,A11)>1,"Si","No") -> No | O11: =VLOOKUP(J11,Referencias!$A$2:$B$7,2,FALSE()) -> Primera | P11: =IF(D11="","Faltante","OK") -> OK | Q11: =IF(L11="","Faltante","OK") -> OK
A12: 1067 | B12: 5 | C12: Paula Lopez | D12: paula.lopez5@correo.co | E12: 16/03/1962 | F12: Ocasional | G12: Santa Marta | H12: Pereira | I12: 23/03/2026 | J12: 2nda | K12: Pagado | L12: 284900 | M12: 10/11/2025 | N12: =IF(COUNTIF($A$2:A12,A12)>1,"Si","No") -> No | O12: =VLOOKUP(J12,Referencias!$A$2:$B$7,2,FALSE()) -> Segunda | P12: =IF(D12="","Faltante","OK") -> OK | Q12: =IF(L12="","Faltante","OK") -> OK
A13: 1007 | B13: 24 | C13: Maria Martinez | D13: maria.martinez24@correo.co | F13: Abonado | G13: Medellin | H13: Cali | I13: 10/06/2026 | J13: 1ra | K13: Anulado | L13: 62500 | M13: 06/02/2026 | N13: =IF(COUNTIF($A$2:A13,A13)>1,"Si","No") -> No | O13: =VLOOKUP(J13,Referencias!$A$2:$B$7,2,FALSE()) -> Primera | P13: =IF(D13="","Faltante","OK") -> OK | Q13: =IF(L13="","Faltante","OK") -> OK
A14: 1089 | B14: 55 | C14: Isabella Gonzalez | D14: isabella.gonzalez55@correo.co | E14: 29/12/1979 | F14: Abonado | G14: Pereira | H14: Santa Marta | I14: 09/06/2026 | J14: segunda | K14: Pagado | L14: 212500 | M14: 18/04/2026 | N14: =IF(COUNTIF($A$2:A14,A14)>1,"Si","No") -> No | O14: =VLOOKUP(J14,Referencias!$A$2:$B$7,2,FALSE()) -> Segunda | P14: =IF(D14="","Faltante","OK") -> OK | Q14: =IF(L14="","Faltante","OK") -> OK
A15: 1054 | B15: 14 | C15: Sebastian Lopez | D15: sebastian.lopez14@correo.co | E15: 05/08/1970 | F15: Abonado | G15: Cali | H15: Bogota Central | I15: 15/04/2026 | J15: 2da | K15: Pagado | L15: 54000 | M15: 13/01/2026 | N15: =IF(COUNTIF($A$2:A15,A15)>1,"Si","No") -> No | O15: =VLOOKUP(J15,Referencias!$A$2:$B$7,2,FALSE()) -> Segunda | P15: =IF(D15="","Faltante","OK") -> OK | Q15: =IF(L15="","Faltante","OK") -> OK
A16: 1070 | B16: 40 | C16: Andres Torres | D16: andres.torres40@correo.co | E16: 03/11/1967 | F16: Abonado | G16: Manizales | H16: Cartagena | I16: 28/04/2026 | J16: primera | K16: Pagado | L16: 172900 | M16: 13/01/2026 | N16: =IF(COUNTIF($A$2:A16,A16)>1,"Si","No") -> No | O16: =VLOOKUP(J16,Referencias!$A$2:$B$7,2,FALSE()) -> Primera | P16: =IF(D16="","Faltante","OK") -> OK | Q16: =IF(L16="","Faltante","OK") -> OK
A17: 1084 | B17: 3 | C17: David Lopez | D17: david.lopez3@correo.co | E17: 16/06/1960 | F17: Ocasional | G17: Pereira | H17: Cucuta | I17: 25/06/2026 | J17: 1era | K17: Pagado | L17: 65200 | M17: 21/11/2025 | N17: =IF(COUNTIF($A$2:A17,A17)>1,"Si","No") -> No | O17: =VLOOKUP(J17,Referencias!$A$2:$B$7,2,FALSE()) -> Primera | P17: =IF(D17="","Faltante","OK") -> OK | Q17: =IF(L17="","Faltante","OK") -> OK
A18: 1060 | B18: 17 | C18: Juan Rodriguez | D18: juan.rodriguez17@correo.co | E18: 02/03/2001 | F18: Abonado | G18: Santa Marta | H18: Manizales | I18: 16/04/2026 | J18: 1era | K18: Pagado | L18: 253000 | M18: 10/04/2026 | N18: =IF(COUNTIF($A$2:A18,A18)>1,"Si","No") -> No | O18: =VLOOKUP(J18,Referencias!$A$2:$B$7,2,FALSE()) -> Primera | P18: =IF(D18="","Faltante","OK") -> OK | Q18: =IF(L18="","Faltante","OK") -> OK
A19: 1051 | B19: 18 | C19: Valentina Gomez | D19: valentina.gomez18@correo.co | E19: 30/04/1966 | F19: Ocasional | G19: Medellin | H19: Bogota Central | I19: 27/05/2026 | J19: primera | K19: Pagado | L19: 95700 | M19: 14/11/2025 | N19: =IF(COUNTIF($A$2:A19,A19)>1,"Si","No") -> No | O19: =VLOOKUP(J19,Referencias!$A$2:$B$7,2,FALSE()) -> Primera | P19: =IF(D19="","Faltante","OK") -> OK | Q19: =IF(L19="","Faltante","OK") -> OK
A20: 1099 | B20: 42 | C20: Manuela Gonzalez | D20: manuela.gonzalez42@correo.co | E20: 17/07/1968 | F20: Ocasional | G20: Medellin | H20: Manizales | I20: 24/04/2026 | J20: 2nda | K20: Pagado | L20: 60400 | M20: 10/03/2026 | N20: =IF(COUNTIF($A$2:A20,A20)>1,"Si","No") -> No | O20: =VLOOKUP(J20,Referencias!$A$2:$B$7,2,FALSE()) -> Segunda | P20: =IF(D20="","Faltante","OK") -> OK | Q20: =IF(L20="","Faltante","OK") -> OK
A21: 1019 | B21: 33 | C21: Mateo Martinez | F21: Abonado | G21: Pereira | H21: Medellin | I21: 26/05/2026 | J21: 1ra | K21: Pagado | M21: 21/11/2025 | N21: =IF(COUNTIF($A$2:A21,A21)>1,"Si","No") -> No | O21: =VLOOKUP(J21,Referencias!$A$2:$B$7,2,FALSE()) -> Primera | P21: =IF(D21="","Faltante","OK") -> Faltante | Q21: =IF(L21="","Faltante","OK") -> Faltante
A22: 1042 | B22: 31 | C22: Santiago Ramirez | E22: 12/02/1975 | F22: Abonado | G22: Bogota Central | H22: Cucuta | I22: 05/03/2026 | J22: 1ra | K22: Anulado | L22: 110600 | M22: 02/03/2026 | N22: =IF(COUNTIF($A$2:A22,A22)>1,"Si","No") -> No | O22: =VLOOKUP(J22,Referencias!$A$2:$B$7,2,FALSE()) -> Primera | P22: =IF(D22="","Faltante","OK") -> Faltante | Q22: =IF(L22="","Faltante","OK") -> OK
A23: 1113 | B23: 30 | C23: Mateo Rodriguez | D23: mateo.rodriguez30@correo.co | E23: 03/02/2003 | F23: Abonado | G23: Santa Marta | H23: Barranquilla | I23: 06/02/2026 | J23: primera | K23: Pagado | L23: 111200 | M23: 15/02/2026 | N23: =IF(COUNTIF($A$2:A23,A23)>1,"Si","No") -> No | O23: =VLOOKUP(J23,Referencias!$A$2:$B$7,2,FALSE()) -> Primera | P23: =IF(D23="","Faltante","OK") -> OK | Q23: =IF(L23="","Faltante","OK") -> OK
A24: 1134 | B24: 4 | C24: Sofia Sanchez | D24: sofia.sanchez4@correo.co | E24: 21/03/1997 | F24: Ocasional | G24: Santa Marta | H24: Bogota Central | I24: 28/01/2026 | J24: 2da | K24: Pagado | L24: 145600 | M24: 12/02/2026 | N24: =IF(COUNTIF($A$2:A24,A24)>1,"Si","No") -> No | O24: =VLOOKUP(J24,Referencias!$A$2:$B$7,2,FALSE()) -> Segunda | P24: =IF(D24="","Faltante","OK") -> OK | Q24: =IF(L24="","Faltante","OK") -> OK
A25: 1001 | B25: 2 | C25: Gabriela Hernandez | D25: gabriela.hernandez2@correo.co | E25: 20/08/1992 | F25: Abonado | G25: Manizales | H25: Cartagena | I25: 02/01/2026 | J25: 1ra | K25: Pagado | L25: 87800 | M25: 15/05/2026 | N25: =IF(COUNTIF($A$2:A25,A25)>1,"Si","No") -> No | O25: =VLOOKUP(J25,Referencias!$A$2:$B$7,2,FALSE()) -> Primera | P25: =IF(D25="","Faltante","OK") -> OK | Q25: =IF(L25="","Faltante","OK") -> OK
A26: 1009 | B26: 57 | C26: Nicolas Ramirez | D26: nicolas.ramirez57@correo.co | E26: 18/07/1964 | F26: Ocasional | G26: Santa Marta | H26: Barranquilla | I26: 09/02/2026 | J26: primera | K26: Anulado | L26: 259100 | M26: 16/03/2026 | N26: =IF(COUNTIF($A$2:A26,A26)>1,"Si","No") -> No | O26: =VLOOKUP(J26,Referencias!$A$2:$B$7,2,FALSE()) -> Primera | P26: =IF(D26="","Faltante","OK") -> OK | Q26: =IF(L26="","Faltante","OK") -> OK
A27: 1023 | B27: 48 | C27: Gabriela Martinez | D27: gabriela.martinez48@correo.co | E27: 05/10/1985 | F27: Abonado | G27: Cartagena | H27: Santa Marta | I27: 06/05/2026 | J27: primera | K27: Reembolsado | L27: 70400 | M27: 17/02/2026 | N27: =IF(COUNTIF($A$2:A27,A27)>1,"Si","No") -> No | O27: =VLOOKUP(J27,Referencias!$A$2:$B$7,2,FALSE()) -> Primera | P27: =IF(D27="","Faltante","OK") -> OK | Q27: =IF(L27="","Faltante","OK") -> OK
A28: 1039 | B28: 55 | C28: Diego Perez | D28: diego.perez55@correo.co | E28: 15/10/1981 | F28: Ocasional | G28: Pereira | H28: Santa Marta | I28: 20/05/2026 | J28: segunda | K28: Anulado | L28: 120100 | M28: 05/03/2026 | N28: =IF(COUNTIF($A$2:A28,A28)>1,"Si","No") -> No | O28: =VLOOKUP(J28,Referencias!$A$2:$B$7,2,FALSE()) -> Segunda | P28: =IF(D28="","Faltante","OK") -> OK | Q28: =IF(L28="","Faltante","OK") -> OK
A29: 1095 | B29: 26 | C29: Valentina Perez | E29: 01/02/1983 | F29: Ocasional | G29: Cucuta | H29: Pereira | I29: 13/06/2026 | J29: 2da | K29: Pagado | L29: 310700 | M29: 14/12/2025 | N29: =IF(COUNTIF($A$2:A29,A29)>1,"Si","No") -> No | O29: =VLOOKUP(J29,Referencias!$A$2:$B$7,2,FALSE()) -> Segunda | P29: =IF(D29="","Faltante","OK") -> Faltante | Q29: =IF(L29="","Faltante","OK") -> OK
A30: 1075 | B30: 59 | C30: Paula Lopez | D30: paula.lopez59@correo.co | E30: 01/05/1965 | F30: Ocasional | G30: Medellin | H30: Cali | I30: 27/02/2026 | J30: 2nda | K30: Pagado | L30: 311000 | M30: 25/05/2026 | N30: =IF(COUNTIF($A$2:A30,A30)>1,"Si","No") -> No | O30: =VLOOKUP(J30,Referencias!$A$2:$B$7,2,FALSE()) -> Segunda | P30: =IF(D30="","Faltante","OK") -> OK | Q30: =IF(L30="","Faltante","OK") -> OK
A31: 1059 | B31: 27 | C31: Juan Gonzalez | D31: juan.gonzalez27@correo.co | E31: 03/08/1984 | F31: Ocasional | G31: Manizales | H31: Cartagena | I31: 19/06/2026 | J31: 2da | K31: Anulado | L31: 170100 | M31: 20/01/2026 | N31: =IF(COUNTIF($A$2:A31,A31)>1,"Si","No") -> No | O31: =VLOOKUP(J31,Referencias!$A$2:$B$7,2,FALSE()) -> Segunda | P31: =IF(D31="","Faltante","OK") -> OK | Q31: =IF(L31="","Faltante","OK") -> OK
A32: 1116 | B32: 30 | C32: Paula Martinez | D32: paula.martinez30@correo.co | F32: Ocasional | G32: Bogota Central | H32: Cartagena | I32: 21/02/2026 | J32: 1era | K32: Anulado | L32: 131800 | M32: 19/01/2026 | N32: =IF(COUNTIF($A$2:A32,A32)>1,"Si","No") -> No | O32: =VLOOKUP(J32,Referencias!$A$2:$B$7,2,FALSE()) -> Primera | P32: =IF(D32="","Faltante","OK") -> OK | Q32: =IF(L32="","Faltante","OK") -> OK
A33: 1008 | B33: 39 | C33: Julian Ramirez | D33: julian.ramirez39@correo.co | E33: 12/01/1956 | F33: Abonado | G33: Santa Marta | H33: Cartagena | I33: 14/06/2026 | J33: primera | K33: Pagado | L33: 169800 | M33: 04/05/2026 | N33: =IF(COUNTIF($A$2:A33,A33)>1,"Si","No") -> No | O33: =VLOOKUP(J33,Referencias!$A$2:$B$7,2,FALSE()) -> Primera | P33: =IF(D33="","Faltante","OK") -> OK | Q33: =IF(L33="","Faltante","OK") -> OK
A34: 1004 | B34: 24 | C34: Daniela Hernandez | D34: daniela.hernandez24@correo.co | E34: 28/05/1961 | F34: Abonado | G34: Santa Marta | H34: Barranquilla | I34: 11/02/2026 | J34: 2da | K34: Pagado | L34: 221000 | M34: 23/03/2026 | N34: =IF(COUNTIF($A$2:A34,A34)>1,"Si","No") -> Si | O34: =VLOOKUP(J34,Referencias!$A$2:$B$7,2,FALSE()) -> Segunda | P34: =IF(D34="","Faltante","OK") -> OK | Q34: =IF(L34="","Faltante","OK") -> OK
A35: 1138 | B35: 33 | C35: David Ramirez | D35: david.ramirez33@correo.co | E35: 09/08/1997 | F35: Abonado | G35: Bucaramanga | H35: Cucuta | I35: 22/06/2026 | J35: 1era | K35: Reembolsado | L35: 264100 | M35: 05/05/2026 | N35: =IF(COUNTIF($A$2:A35,A35)>1,"Si","No") -> No | O35: =VLOOKUP(J35,Referencias!$A$2:$B$7,2,FALSE()) -> Primera | P35: =IF(D35="","Faltante","OK") -> OK | Q35: =IF(L35="","Faltante","OK") -> OK
A36: 1011 | B36: 53 | C36: Mateo Ramirez | D36: mateo.ramirez53@correo.co | E36: 22/08/1997 | F36: Abonado | G36: Cartagena | H36: Santa Marta | I36: 05/06/2026 | J36: 2da | K36: Reembolsado | L36: 252700 | M36: 26/04/2026 | N36: =IF(COUNTIF($A$2:A36,A36)>1,"Si","No") -> No | O36: =VLOOKUP(J36,Referencias!$A$2:$B$7,2,FALSE()) -> Segunda | P36: =IF(D36="","Faltante","OK") -> OK | Q36: =IF(L36="","Faltante","OK") -> OK
A37: 1002 | B37: 22 | C37: Isabella Rodriguez | D37: isabella.rodriguez22@correo.co | E37: 09/11/1985 | F37: Ocasional | G37: Bogota Central | H37: Manizales | I37: 18/05/2026 | J37: 1era | K37: Reembolsado | L37: 196800 | M37: 01/06/2026 | N37: =IF(COUNTIF($A$2:A37,A37)>1,"Si","No") -> No | O37: =VLOOKUP(J37,Referencias!$A$2:$B$7,2,FALSE()) -> Primera | P37: =IF(D37="","Faltante","OK") -> OK | Q37: =IF(L37="","Faltante","OK") -> OK
A38: 1072 | B38: 37 | C38: Daniela Torres | D38: daniela.torres37@correo.co | E38: 19/12/1956 | F38: Ocasional | G38: Cartagena | H38: Bogota Central | I38: 25/05/2026 | J38: 2nda | K38: Anulado | L38: 295400 | M38: 10/05/2026 | N38: =IF(COUNTIF($A$2:A38,A38)>1,"Si","No") -> No | O38: =VLOOKUP(J38,Referencias!$A$2:$B$7,2,FALSE()) -> Segunda | P38: =IF(D38="","Faltante","OK") -> OK | Q38: =IF(L38="","Faltante","OK") -> OK
A39: 1014 | B39: 37 | C39: Diego Sanchez | D39: diego.sanchez37@correo.co | E39: 09/07/1991 | F39: Abonado | G39: Medellin | H39: Cucuta | I39: 18/06/2026 | J39: 2da | K39: Pagado | L39: 282600 | M39: 14/11/2025 | N39: =IF(COUNTIF($A$2:A39,A39)>1,"Si","No") -> No | O39: =VLOOKUP(J39,Referencias!$A$2:$B$7,2,FALSE()) -> Segunda | P39: =IF(D39="","Faltante","OK") -> OK | Q39: =IF(L39="","Faltante","OK") -> OK
A40: 1119 | B40: 35 | C40: Sofia Gonzalez | E40: 10/07/1981 | F40: Ocasional | G40: Manizales | H40: Pereira | I40: 12/02/2026 | J40: 2nda | K40: Pagado | L40: 244900 | M40: 22/06/2026 | N40: =IF(COUNTIF($A$2:A40,A40)>1,"Si","No") -> No | O40: =VLOOKUP(J40,Referencias!$A$2:$B$7,2,FALSE()) -> Segunda | P40: =IF(D40="","Faltante","OK") -> Faltante | Q40: =IF(L40="","Faltante","OK") -> OK
...

Sheet Analisis_Formulas
A1: Analisis de la base Billetes_Brutos
A2: Rango de datos: Billetes_Brutos!A2:M147 (146 filas)
A4: 1. CONTAR.BLANCO (COUNTBLANK) - valores faltantes
A5: Correos faltantes | B5: =COUNTBLANK(Billetes_Brutos!D2:D147) -> 29
A6: Fechas de nacimiento faltantes | B6: =COUNTBLANK(Billetes_Brutos!E2:E147) -> 15
A7: Precios faltantes | B7: =COUNTBLANK(Billetes_Brutos!L2:L147) -> 5
A9: 2. CONTARA (COUNTA) - celdas no vacias
A10: Numero total de billetes registrados | B10: =COUNTA(Billetes_Brutos!A2:A147) -> 146
A11: Numero de estaciones de salida registradas | B11: =COUNTA(Billetes_Brutos!G2:G147) -> 146
A13: 3. CONTAR.SI (COUNTIF) - conteo con un criterio
A14: Billetes anulados | B14: =COUNTIF(Billetes_Brutos!K2:K147,"Anulado") -> 20
A15: Billetes reembolsados | B15: =COUNTIF(Billetes_Brutos!K2:K147,"Reembolsado") -> 17
A16: Billetes primera clase (etiqueta exacta "1era") | B16: =COUNTIF(Billetes_Brutos!J2:J147,"1era") -> 18
A17: Clientes abonados (tipo_cliente) | B17: =COUNTIF(Billetes_Brutos!F2:F147,"Abonado") -> 62
A19: 4. CONTAR.SI multicriterio (dos CONTAR.SI combinados / CONTAR.SI.CONJUNTO)
A20: Billetes primera clase Y anulados (SUMAPRODUCTO multicriterio) | B20: =SUMPRODUCT((Billetes_Brutos!J2:J147="1era")*(Billetes_Brutos!K2:K147="Anulado")) -> 3
A21: Lo mismo con CONTAR.SI.CONJUNTO (equivalente nativo) | B21: =COUNTIFS(Billetes_Brutos!J2:J147,"1era",Billetes_Brutos!K2:K147,"Anulado") -> 3
A23: 5. SUMAPRODUCTO(CONTAR.SI(...)) - conteo sobre varios valores (OR)
A24: Billetes primera clase, todas las variantes (1era/1ra/primera) | B24: =SUMPRODUCT(COUNTIF(Billetes_Brutos!J2:J147,{"1era";"1ra";"primera"})) -> 70
A25: Billetes segunda clase, todas las variantes (2da/segunda/2nda) | B25: =SUMPRODUCT(COUNTIF(Billetes_Brutos!J2:J147,{"2da";"segunda";"2nda"})) -> 76
A27: 6. Deteccion de duplicados (id_billete) con SUMAPRODUCTO
A28: Numero de filas duplicadas (id_billete que aparece mas de una vez) | B28: =SUMPRODUCT((COUNTIF(Billetes_Brutos!A2:A147,Billetes_Brutos!A2:A147)>1)*1) -> 12
A30: 7. Indicador de negocio: billetes pagados por estacion de salida
A31: Ej. billetes pagados desde Bogota Central | B31: =COUNTIFS(Billetes_Brutos!G2:G147,"Bogota Central",Billetes_Brutos!K2:K147,"Pagado") -> 3
A32: Ingreso total en COP (billetes pagados) | B32: =SUMIF(Billetes_Brutos!K2:K147,"Pagado",Billetes_Brutos!L2:L147) -> 19879100
A34: 8. Comparacion Bruto vs Limpio (efecto del ETL)
A35: Numero de billetes - Bruto | B35: =COUNTA(Billetes_Brutos!A2:A147) -> 146
A36: Numero de billetes - Limpio (sin duplicados) | B36: =COUNTA(Billetes_Limpios!A2:A141) -> 140
A37: Correos senalados como "Sin correo" (originalmente vacios) - Limpio | B37: =COUNTIF(Billetes_Limpios!D2:D141,"Sin correo") -> 27
A38: Precios por confirmar - Limpio | B38: =COUNTIF(Billetes_Limpios!L2:L141,"Por confirmar") -> 5
A39: Ingreso real (COP) - Limpio, solo pagados | B39: =SUMIF(Billetes_Limpios!K2:K141,"Pagado",Billetes_Limpios!L2:L141) -> 18664300

Sheet Referencias
A1: Variante en Billetes_Brutos | B1: Clase uniforme
A2: 1era | B2: Primera
A3: 1ra | B3: Primera
A4: primera | B4: Primera
A5: 2da | B5: Segunda
A6: segunda | B6: Segunda
A7: 2nda | B7: Segunda
A9: Tabla usada por la columna 'Clase_Uniforme' en Billetes_Brutos (VLOOKUP) para uniformizar las variantes de la columna 'clase'.

Sheet Billetes_Limpios
A1: id_billete | B1: id_cliente | C1: nombre_cliente | D1: correo | E1: fecha_nacimiento | F1: tipo_cliente | G1: estacion_salida | H1: estacion_llegada | I1: fecha_viaje | J1: clase | K1: estado | L1: precio | M1: fecha_compra
A2: =Billetes_Brutos!A2 -> 1047 | B2: =Billetes_Brutos!B2 -> 22 | C2: =Billetes_Brutos!C2 -> Santiago Sanchez | D2: =IF(Billetes_Brutos!D2="","Sin correo",Billetes_Brutos!D2) -> santiago.sanchez22@correo.co | E2: =IF(Billetes_Brutos!E2="","No disponible",Billetes_Brutos!E2) -> 11/01/1974 | F2: =Billetes_Brutos!F2 -> Ocasional | G2: =Billetes_Brutos!G2 -> Cartagena | H2: =Billetes_Brutos!H2 -> Bucaramanga | I2: =Billetes_Brutos!I2 -> 13/03/2026 | J2: =Billetes_Brutos!O2 -> Segunda | K2: =Billetes_Brutos!K2 -> Pagado | L2: =IF(Billetes_Brutos!L2="","Por confirmar",Billetes_Brutos!L2) -> 47800 | M2: =Billetes_Brutos!M2 -> 19/12/2025
A3: =Billetes_Brutos!A3 -> 1079 | B3: =Billetes_Brutos!B3 -> 45 | C3: =Billetes_Brutos!C3 -> Gabriela Perez | D3: =IF(Billetes_Brutos!D3="","Sin correo",Billetes_Brutos!D3) -> gabriela.perez45@correo.co | E3: =IF(Billetes_Brutos!E3="","No disponible",Billetes_Brutos!E3) -> 21/03/1992 | F3: =Billetes_Brutos!F3 -> Abonado | G3: =Billetes_Brutos!G3 -> Manizales | H3: =Billetes_Brutos!H3 -> Pereira | I3: =Billetes_Brutos!I3 -> 13/03/2026 | J3: =Billetes_Brutos!O3 -> Primera | K3: =Billetes_Brutos!K3 -> Pagado | L3: =IF(Billetes_Brutos!L3="","Por confirmar",Billetes_Brutos!L3) -> 167300 | M3: =Billetes_Brutos!M3 -> 31/12/2025
A4: =Billetes_Brutos!A4 -> 1016 | B4: =Billetes_Brutos!B4 -> 60 | C4: =Billetes_Brutos!C4 -> Mateo Sanchez | D4: =IF(Billetes_Brutos!D4="","Sin correo",Billetes_Brutos!D4) -> mateo.sanchez60@correo.co | E4: =IF(Billetes_Brutos!E4="","No disponible",Billetes_Brutos!E4) -> 14/10/1963 | F4: =Billetes_Brutos!F4 -> Abonado | G4: =Billetes_Brutos!G4 -> Santa Marta | H4: =Billetes_Brutos!H4 -> Bogota Central | I4: =Billetes_Brutos!I4 -> 24/01/2026 | J4: =Billetes_Brutos!O4 -> Primera | K4: =Billetes_Brutos!K4 -> Pagado | L4: =IF(Billetes_Brutos!L4="","Por confirmar",Billetes_Brutos!L4) -> 103800 | M4: =Billetes_Brutos!M4 -> 11/02/2026
A5: =Billetes_Brutos!A5 -> 1057 | B5: =Billetes_Brutos!B5 -> 29 | C5: =Billetes_Brutos!C5 -> Mateo Torres | D5: =IF(Billetes_Brutos!D5="","Sin correo",Billetes_Brutos!D5) -> Sin correo | E5: =IF(Billetes_Brutos!E5="","No disponible",Billetes_Brutos!E5) -> 01/12/1983 | F5: =Billetes_Brutos!F5 -> Ocasional | G5: =Billetes_Brutos!G5 -> Bogota Central | H5: =Billetes_Brutos!H5 -> Medellin | I5: =Billetes_Brutos!I5 -> 28/02/2026 | J5: =Billetes_Brutos!O5 -> Segunda | K5: =Billetes_Brutos!K5 -> Anulado | L5: =IF(Billetes_Brutos!L5="","Por confirmar",Billetes_Brutos!L5) -> 306500 | M5: =Billetes_Brutos!M5 -> 15/05/2026
A6: =Billetes_Brutos!A6 -> 1076 | B6: =Billetes_Brutos!B6 -> 36 | C6: =Billetes_Brutos!C6 -> Daniela Rodriguez | D6: =IF(Billetes_Brutos!D6="","Sin correo",Billetes_Brutos!D6) -> daniela.rodriguez36@correo.co | E6: =IF(Billetes_Brutos!E6="","No disponible",Billetes_Brutos!E6) -> No disponible | F6: =Billetes_Brutos!F6 -> Abonado | G6: =Billetes_Brutos!G6 -> Manizales | H6: =Billetes_Brutos!H6 -> Bucaramanga | I6: =Billetes_Brutos!I6 -> 22/06/2026 | J6: =Billetes_Brutos!O6 -> Segunda | K6: =Billetes_Brutos!K6 -> Pagado | L6: =IF(Billetes_Brutos!L6="","Por confirmar",Billetes_Brutos!L6) -> 271200 | M6: =Billetes_Brutos!M6 -> 04/02/2026
A7: =Billetes_Brutos!A7 -> 1022 | B7: =Billetes_Brutos!B7 -> 24 | C7: =Billetes_Brutos!C7 -> Sofia Martinez | D7: =IF(Billetes_Brutos!D7="","Sin correo",Billetes_Brutos!D7) -> sofia.martinez24@correo.co | E7: =IF(Billetes_Brutos!E7="","No disponible",Billetes_Brutos!E7) -> 20/02/1982 | F7: =Billetes_Brutos!F7 -> Abonado | G7: =Billetes_Brutos!G7 -> Santa Marta | H7: =Billetes_Brutos!H7 -> Cartagena | I7: =Billetes_Brutos!I7 -> 19/06/2026 | J7: =Billetes_Brutos!O7 -> Primera | K7: =Billetes_Brutos!K7 -> Reembolsado | L7: =IF(Billetes_Brutos!L7="","Por confirmar",Billetes_Brutos!L7) -> 76700 | M7: =Billetes_Brutos!M7 -> 28/11/2025
A8: =Billetes_Brutos!A8 -> 1065 | B8: =Billetes_Brutos!B8 -> 56 | C8: =Billetes_Brutos!C8 -> Sebastian Hernandez | D8: =IF(Billetes_Brutos!D8="","Sin correo",Billetes_Brutos!D8) -> sebastian.hernandez56@correo.co | E8: =IF(Billetes_Brutos!E8="","No disponible",Billetes_Brutos!E8) -> 08/11/1991 | F8: =Billetes_Brutos!F8 -> Abonado | G8: =Billetes_Brutos!G8 -> Bucaramanga | H8: =Billetes_Brutos!H8 -> Manizales | I8: =Billetes_Brutos!I8 -> 30/06/2026 | J8: =Billetes_Brutos!O8 -> Segunda | K8: =Billetes_Brutos!K8 -> Pagado | L8: =IF(Billetes_Brutos!L8="","Por confirmar",Billetes_Brutos!L8) -> 270700 | M8: =Billetes_Brutos!M8 -> 09/12/2025
A9: =Billetes_Brutos!A9 -> 1004 | B9: =Billetes_Brutos!B9 -> 24 | C9: =Billetes_Brutos!C9 -> Daniela Hernandez | D9: =IF(Billetes_Brutos!D9="","Sin correo",Billetes_Brutos!D9) -> daniela.hernandez24@correo.co | E9: =IF(Billetes_Brutos!E9="","No disponible",Billetes_Brutos!E9) -> 28/05/1961 | F9: =Billetes_Brutos!F9 -> Abonado | G9: =Billetes_Brutos!G9 -> Santa Marta | H9: =Billetes_Brutos!H9 -> Barranquilla | I9: =Billetes_Brutos!I9 -> 11/02/2026 | J9: =Billetes_Brutos!O9 -> Segunda | K9: =Billetes_Brutos!K9 -> Pagado | L9: =IF(Billetes_Brutos!L9="","Por confirmar",Billetes_Brutos!L9) -> 221000 | M9: =Billetes_Brutos!M9 -> 23/03/2026
A10: =Billetes_Brutos!A10 -> 1115 | B10: =Billetes_Brutos!B10 -> 51 | C10: =Billetes_Brutos!C10 -> Mateo Gonzalez | D10: =IF(Billetes_Brutos!D10="","Sin correo",Billetes_Brutos!D10) -> mateo.gonzalez51@correo.co | E10: =IF(Billetes_Brutos!E10="","No disponible",Billetes_Brutos!E10) -> 19/04/1964 | F10: =Billetes_Brutos!F10 -> Ocasional | G10: =Billetes_Brutos!G10 -> Cali | H10: =Billetes_Brutos!H10 -> Bogota Central | I10: =Billetes_Brutos!I10 -> 01/04/2026 | J10: =Billetes_Brutos!O10 -> Segunda | K10: =Billetes_Brutos!K10 -> Pagado | L10: =IF(Billetes_Brutos!L10="","Por confirmar",Billetes_Brutos!L10) -> 273400 | M10: =Billetes_Brutos!M10 -> 25/04/2026
A11: =Billetes_Brutos!A11 -> 1064 | B11: =Billetes_Brutos!B11 -> 47 | C11: =Billetes_Brutos!C11 -> Sofia Torres | D11: =IF(Billetes_Brutos!D11="","Sin correo",Billetes_Brutos!D11) -> sofia.torres47@correo.co | E11: =IF(Billetes_Brutos!E11="","No disponible",Billetes_Brutos!E11) -> 01/05/1968 | F11: =Billetes_Brutos!F11 -> Ocasional | G11: =Billetes_Brutos!G11 -> Santa Marta | H11: =Billetes_Brutos!H11 -> Manizales | I11: =Billetes_Brutos!I11 -> 30/03/2026 | J11: =Billetes_Brutos!O11 -> Primera | K11: =Billetes_Brutos!K11 -> Pagado | L11: =IF(Billetes_Brutos!L11="","Por confirmar",Billetes_Brutos!L11) -> 170200 | M11: =Billetes_Brutos!M11 -> 22/01/2026
A12: =Billetes_Brutos!A12 -> 1067 | B12: =Billetes_Brutos!B12 -> 5 | C12: =Billetes_Brutos!C12 -> Paula Lopez | D12: =IF(Billetes_Brutos!D12="","Sin correo",Billetes_Brutos!D12) -> paula.lopez5@correo.co | E12: =IF(Billetes_Brutos!E12="","No disponible",Billetes_Brutos!E12) -> 16/03/1962 | F12: =Billetes_Brutos!F12 -> Ocasional | G12: =Billetes_Brutos!G12 -> Santa Marta | H12: =Billetes_Brutos!H12 -> Pereira | I12: =Billetes_Brutos!I12 -> 23/03/2026 | J12: =Billetes_Brutos!O12 -> Segunda | K12: =Billetes_Brutos!K12 -> Pagado | L12: =IF(Billetes_Brutos!L12="","Por confirmar",Billetes_Brutos!L12) -> 284900 | M12: =Billetes_Brutos!M12 -> 10/11/2025
A13: =Billetes_Brutos!A13 -> 1007 | B13: =Billetes_Brutos!B13 -> 24 | C13: =Billetes_Brutos!C13 -> Maria Martinez | D13: =IF(Billetes_Brutos!D13="","Sin correo",Billetes_Brutos!D13) -> maria.martinez24@correo.co | E13: =IF(Billetes_Brutos!E13="","No disponible",Billetes_Brutos!E13) -> No disponible | F13: =Billetes_Brutos!F13 -> Abonado | G13: =Billetes_Brutos!G13 -> Medellin | H13: =Billetes_Brutos!H13 -> Cali | I13: =Billetes_Brutos!I13 -> 10/06/2026 | J13: =Billetes_Brutos!O13 -> Primera | K13: =Billetes_Brutos!K13 -> Anulado | L13: =IF(Billetes_Brutos!L13="","Por confirmar",Billetes_Brutos!L13) -> 62500 | M13: =Billetes_Brutos!M13 -> 06/02/2026
... A33: =Billetes_Brutos!A33 -> 1008 | B33: =Billetes_Brutos!B33 -> 39 | C33: =Billetes_Brutos!C33 -> Julian Ramirez | D33: =IF(Billetes_Brutos!D33="","Sin correo",Billetes_Brutos!D33) -> julian.ramirez39@correo.co | E33: =IF(Billetes_Brutos!E33="","No disponible",Billetes_Brutos!E33) -> 12/01/1956 | F33: =Billetes_Brutos!F33 -> Abonado | G33: =Billetes_Brutos!G33 -> Santa Marta | H33: =Billetes_Brutos!H33 -> Cartagena | I33: =Billetes_Brutos!I33 -> 14/06/2026 | J33: =Billetes_Brutos!O33 -> Primera | K33: =Billetes_Brutos!K33 -> Pagado | L33: =IF(Billetes_Brutos!L33="","Por confirmar",Billetes_Brutos!L33) -> 169800 | M33: =Billetes_Brutos!M33 -> 04/05/2026
A34: =Billetes_Brutos!A35 -> 1138 | B34: =Billetes_Brutos!B35 -> 33 | C34: =Billetes_Brutos!C35 -> David Ramirez | D34: =IF(Billetes_Brutos!D35="","Sin correo",Billetes_Brutos!D35) -> david.ramirez33@correo.co | E34: =IF(Billetes_Brutos!E35="","No disponible",Billetes_Brutos!E35) -> 09/08/1997 | F34: =Billetes_Brutos!F35 -> Abonado | G34: =Billetes_Brutos!G35 -> Bucaramanga | H34: =Billetes_Brutos!H35 -> Cucuta | I34: =Billetes_Brutos!I35 -> 22/06/2026 | J34: =Billetes_Brutos!O35 -> Primera | K34: =Billetes_Brutos!K35 -> Reembolsado | L34: =IF(Billetes_Brutos!L35="","Por confirmar",Billetes_Brutos!L35) -> 264100 | M34: =Billetes_Brutos!M35 -> 05/05/2026
A35: =Billetes_Brutos!A36 -> 1011 | B35: =Billetes_Brutos!B36 -> 53 | C35: =Billetes_Brutos!C36 -> Mateo Ramirez | D35: =IF(Billetes_Brutos!D36="","Sin correo",Billetes_Brutos!D36) -> mateo.ramirez53@correo.co | E35: =IF(Billetes_Brutos!E36="","No disponible",Billetes_Brutos!E36) -> 22/08/1997 | F35: =Billetes_Brutos!F36 -> Abonado | G35: =Billetes_Brutos!G36 -> Cartagena | H35: =Billetes_Brutos!H36 -> Santa Marta | I35: =Billetes_Brutos!I36 -> 05/06/2026 | J35: =Billetes_Brutos!O36 -> Segunda | K35: =Billetes_Brutos!K36 -> Reembolsado | L35: =IF(Billetes_Brutos!L36="","Por confirmar",Billetes_Brutos!L36) -> 252700 | M35: =Billetes_Brutos!M36 -> 26/04/2026
A36: =Billetes_Brutos!A37 -> 1002 | B36: =Billetes_Brutos!B37 -> 22 | C36: =Billetes_Brutos!C37 -> Isabella Rodriguez | D36: =IF(Billetes_Brutos!D37="","Sin correo",Billetes_Brutos!D37) -> isabella.rodriguez22@correo.co | E36: =IF(Billetes_Brutos!E37="","No disponible",Billetes_Brutos!E37) -> 09/11/1985 | F36: =Billetes_Brutos!F37 -> Ocasional | G36: =Billetes_Brutos!G37 -> Bogota Central | H36: =Billetes_Brutos!H37 -> Manizales | I36: =Billetes_Brutos!I37 -> 18/05/2026 | J36: =Billetes_Brutos!O37 -> Primera | K36: =Billetes_Brutos!K37 -> Reembolsado | L36: =IF(Billetes_Brutos!L37="","Por confirmar",Billetes_Brutos!L37) -> 196800 | M36: =Billetes_Brutos!M37 -> 01/06/2026
A37: =Billetes_Brutos!A38 -> 1072 | B37: =Billetes_Brutos!B38 -> 37 | C37: =Billetes_Brutos!C38 -> Daniela Torres | D37: =IF(Billetes_Brutos!D38="","Sin correo",Billetes_Brutos!D38) -> daniela.torres37@correo.co | E37: =IF(Billetes_Brutos!E38="","No disponible",Billetes_Brutos!E38) -> 19/12/1956 | F37: =Billetes_Brutos!F38 -> Ocasional | G37: =Billetes_Brutos!G38 -> Cartagena | H37: =Billetes_Brutos!H38 -> Bogota Central | I37: =Billetes_Brutos!I38 -> 25/05/2026 | J37: =Billetes_Brutos!O38 -> Segunda | K37: =Billetes_Brutos!K38 -> Anulado | L37: =IF(Billetes_Brutos!L38="","Por confirmar",Billetes_Brutos!L38) -> 295400 | M37: =Billetes_Brutos!M38 -> 10/05/2026
A38: =Billetes_Brutos!A39 -> 1014 | B38: =Billetes_Brutos!B39 -> 37 | C38: =Billetes_Brutos!C39 -> Diego Sanchez | D38: =IF(Billetes_Brutos!D39="","Sin correo",Billetes_Brutos!D39) -> diego.sanchez37@correo.co | E38: =IF(Billetes_Brutos!E39="","No disponible",Billetes_Brutos!E39) -> 09/07/1991 | F38: =Billetes_Brutos!F39 -> Abonado | G38: =Billetes_Brutos!G39 -> Medellin | H38: =Billetes_Brutos!H39 -> Cucuta | I38: =Billetes_Brutos!I39 -> 18/06/2026 | J38: =Billetes_Brutos!O39 -> Segunda | K38: =Billetes_Brutos!K39 -> Pagado | L38: =IF(Billetes_Brutos!L39="","Por confirmar",Billetes_Brutos!L39) -> 282600 | M38: =Billetes_Brutos!M39 -> 14/11/2025
A39: =Billetes_Brutos!A40 -> 1119 | B39: =Billetes_Brutos!B40 -> 35 | C39: =Billetes_Brutos!C40 -> Sofia Gonzalez | D39: =IF(Billetes_Brutos!D40="","Sin correo",Billetes_Brutos!D40) -> Sin correo | E39: =IF(Billetes_Brutos!E40="","No disponible",Billetes_Brutos!E40) -> 10/07/1981 | F39: =Billetes_Brutos!F40 -> Ocasional | G39: =Billetes_Brutos!G40 -> Manizales | H39: =Billetes_Brutos!H40 -> Pereira | I39: =Billetes_Brutos!I40 -> 12/02/2026 | J39: =Billetes_Brutos!O40 -> Segunda | K39: =Billetes_Brutos!K40 -> Pagado | L39: =IF(Billetes_Brutos!L40="","Por confirmar",Billetes_Brutos!L40) -> 244900 | M39: =Billetes_Brutos!M40 -> 22/06/2026
A40: =Billetes_Brutos!A41 -> 1133 | B40: =Billetes_Brutos!B41 -> 49 | C40: =Billetes_Brutos!C41 -> Camila Sanchez | D40: =IF(Billetes_Brutos!D41="","Sin correo",Billetes_Brutos!D41) -> camila.sanchez49@correo.co | E40: =IF(Billetes_Brutos!E41="","No disponible",Billetes_Brutos!E41) -> 06/09/1982 | F40: =Billetes_Brutos!F41 -> Ocasional | G40: =Billetes_Brutos!G41 -> Bogota Central | H40: =Billetes_Brutos!H41 -> Medellin | I40: =Billetes_Brutos!I41 -> 11/04/2026 | J40: =Billetes_Brutos!O41 -> Segunda | K40: =Billetes_Brutos!K41 -> Pagado | L40: =IF(Billetes_Brutos!L41="","Por confirmar",Billetes_Brutos!L41) -> 205400 | M40: =Billetes_Brutos!M41 -> 13/11/2025
A41: =Billetes_Brutos!A42 -> 1003 | B41: =Billetes_Brutos!B42 -> 41 | C41: =Billetes_Brutos!C42 -> Manuela Gonzalez | D41: =IF(Billetes_Brutos!D42="","Sin correo",Billetes_Brutos!D42) -> manuela.gonzalez41@correo.co | E41: =IF(Billetes_Brutos!E42="","No disponible",Billetes_Brutos!E42) -> 10/02/1959 | F41: =Billetes_Brutos!F42 -> Abonado | G41: =Billetes_Brutos!G42 -> Cartagena | H41: =Billetes_Brutos!H42 -> Medellin | I41: =Billetes_Brutos!I42 -> 01/03/2026 | J41: =Billetes_Brutos!O42 -> Primera | K41: =Billetes_Brutos!K42 -> Pagado | L41: =IF(Billetes_Brutos!L42="","Por confirmar",Billetes_Brutos!L42) -> 274400 | M41: =Billetes_Brutos!M42 -> 12/12/2025
A42: =Billetes_Brutos!A43 -> 1046 | B42: =Billetes_Brutos!B43 -> 52 | C42: =Billetes_Brutos!C43 -> Gabriela Sanchez | D42: =IF(Billetes_Brutos!D43="","Sin correo",Billetes_Brutos!D43) -> gabriela.sanchez52@correo.co | E42: =IF(Billetes_Brutos!E43="","No disponible",Billetes_Brutos!E43) -> 29/01/1979 | F42: =Billetes_Brutos!F43 -> Ocasional | G42: =Billetes_Brutos!G43 -> Barranquilla | H42: =Billetes_Brutos!H43 -> Medellin | I42: =Billetes_Brutos!I43 -> 13/03/2026 | J42: =Billetes_Brutos!O43 -> Segunda | K42: =Billetes_Brutos!K43 -> Pagado | L42: =IF(Billetes_Brutos!L43="","Por confirmar",Billetes_Brutos!L43) -> 212800 | M42: =Billetes_Brutos!M43 -> 06/02/2026
A43: =Billetes_Brutos!A44 -> 1130 | B43: =Billetes_Brutos!B44 -> 27 | C43: =Billetes_Brutos!C44 -> Manuela Gomez | D43: =IF(Billetes_Brutos!D44="","Sin correo",Billetes_Brutos!D44) -> manuela.gomez27@correo.co | E43: =IF(Billetes_Brutos!E44="","No disponible",Billetes_Brutos!E44) -> 26/12/1980 | F43: =Billetes_Brutos!F44 -> Ocasional | G43: =Billetes_Brutos!G44 -> Manizales | H43: =Billetes_Brutos!H44 -> Barranquilla | I43: =Billetes_Brutos!I44 -> 25/06/2026 | J43: =Billetes_Brutos!O44 -> Segunda | K43: =Billetes_Brutos!K44 -> Pagado | L43: =IF(Billetes_Brutos!L44="","Por confirmar",Billetes_Brutos!L44) -> 61500 | M43: =Billetes_Brutos!M44 -> 21/02/2026
A44: =Billetes_Brutos!A45 -> 1020 | B44: =Billetes_Brutos!B45 -> 27 | C44: =Billetes_Brutos!C45 -> Diego Torres | D44: =IF(Billetes_Brutos!D45="","Sin correo",Billetes_Brutos!D45) -> diego.torres27@correo.co | E44: =IF(Billetes_Brutos!E45="","No disponible",Billetes_Brutos!E45) -> 29/04/1973 | F44: =Billetes_Brutos!F45 -> Ocasional | G44: =Billetes_Brutos!G45 -> Barranquilla | H44: =Billetes_Brutos!H45 -> Cartagena | I44: =Billetes_Brutos!I45 -> 12/04/2026 | J44: =Billetes_Brutos!O45 -> Primera | K44: =Billetes_Brutos!K45 -> Pagado | L44: =IF(Billetes_Brutos!L45="","Por confirmar",Billetes_Brutos!L45) -> 131900 | M44: =Billetes_Brutos!M45 -> 12/05/2026
A45: =Billetes_Brutos!A46 -> 1085 | B45: =Billetes_Brutos!B46 -> 21 | C45: =Billetes_Brutos!C46 -> Manuela Martinez | D45: =IF(Billetes_Brutos!D46="","Sin correo",Billetes_Brutos!D46) -> Sin correo | E45: =IF(Billetes_Brutos!E46="","No disponible",Billetes_Brutos!E46) -> 12/03/2004 | F45: =Billetes_Brutos!F46 -> Ocasional | G45: =Billetes_Brutos!G46 -> Pereira | H45: =Billetes_Brutos!H46 -> Santa Marta | I45: =Billetes_Brutos!I46 -> 17/03/2026 | J45: =Billetes_Brutos!O46 -> Segunda | K45: =Billetes_Brutos!K46 -> Pagado | L45: =IF(Billetes_Brutos!L46="","Por confirmar",Billetes_Brutos!L46) -> 263100 | M45: =Billetes_Brutos!M46 -> 30/11/2025
... A54: =Billetes_Brutos!A55 -> 1000 | B54: =Billetes_Brutos!B55 -> 41 | C54: =Billetes_Brutos!C55 -> Isabella Gomez | D54: =IF(Billetes_Brutos!D55="","Sin correo",Billetes_Brutos!D55) -> isabella.gomez41@correo.co | E54: =IF(Billetes_Brutos!E55="","No disponible",Billetes_Brutos!E55) -> 09/07/1967 | F54: =Billetes_Brutos!F55 -> Abonado | G54: =Billetes_Brutos!G55 -> Santa Marta | H54: =Billetes_Brutos!H55 -> Medellin | I54: =Billetes_Brutos!I55 -> 01/06/2026 | J54: =Billetes_Brutos!O55 -> Segunda | K54: =Billetes_Brutos!K55 -> Pagado | L54: =IF(Billetes_Brutos!L55="","Por confirmar",Billetes_Brutos!L55) -> 109000 | M54: =Billetes_Brutos!M55 -> 04/04/2026
A55: =Billetes_Brutos!A57 -> 1049 | B55: =Billetes_Brutos!B57 -> 24 | C55: =Billetes_Brutos!C57 -> Paula Ramirez | D55: =IF(Billetes_Brutos!D57="","Sin correo",Billetes_Brutos!D57) -> paula.ramirez24@correo.co | E55: =IF(Billetes_Brutos!E57="","No disponible",Billetes_Brutos!E57) -> 18/05/2004 | F55: =Billetes_Brutos!F57 -> Ocasional | G55: =Billetes_Brutos!G57 -> Bucaramanga | H55: =Billetes_Brutos!H57 -> Manizales | I55: =Billetes_Brutos!I57 -> 11/03/2026 | J55: =Billetes_Brutos!O57 -> Primera | K55: =Billetes_Brutos!K57 -> Pagado | L55: =IF(Billetes_Brutos!L57="","Por confirmar",Billetes_Brutos!L57) -> 98000 | M55: =Billetes_Brutos!M57 -> 01/12/2025
A56: =Billetes_Brutos!A58 -> 1043 | B56: =Billetes_Brutos!B58 -> 43 | C56: =Billetes_Brutos!C58 -> Isabella Torres | D56: =IF(Billetes_Brutos!D58="","Sin correo",Billetes_Brutos!D58) -> isabella.torres43@correo.co | E56: =IF(Billetes_Brutos!E58="","No disponible",Billetes_Brutos!E58) -> 27/12/1977 | F56: =Billetes_Brutos!F58 -> Ocasional | G56: =Billetes_Brutos!G58 -> Cali | H56: =Billetes_Brutos!H58 -> Medellin | I56: =Billetes_Brutos!I58 -> 11/02/2026 | J56: =Billetes_Brutos!O58 -> Primera | K56: =Billetes_Brutos!K58 -> Pagado | L56: =IF(Billetes_Brutos!L58="","Por confirmar",Billetes_Brutos!L58) -> Por confirmar | M56: =Billetes_Brutos!M58 -> 19/01/2026
A57: =Billetes_Brutos!A59 -> 1100 | B57: =Billetes_Brutos!B59 -> 5 | C57: =Billetes_Brutos!C59 -> Sofia Sanchez | D57: =IF(Billetes_Brutos!D59="","Sin correo",Billetes_Brutos!D59) -> sofia.sanchez5@correo.co | E57: =IF(Billetes_Brutos!E59="","No disponible",Billetes_Brutos!E59) -> No disponible | F57: =Billetes_Brutos!F59 -> Ocasional | G57: =Billetes_Brutos!G59 -> Medellin | H57: =Billetes_Brutos!H59 -> Cucuta | I57: =Billetes_Brutos!I59 -> 07/06/2026 | J57: =Billetes_Brutos!O59 -> Segunda | K57: =Billetes_Brutos!K59 -> Pagado | L57: =IF(Billetes_Brutos!L59="","Por confirmar",Billetes_Brutos!L59) -> 197400 | M57: =Billetes_Brutos!M59 -> 22/05/2026
A58: =Billetes_Brutos!A60 -> 1074 | B58: =Billetes_Brutos!B60 -> 47 | C58: =Billetes_Brutos!C60 -> Samuel Rodriguez | D58: =IF(Billetes_Brutos!D60="","Sin correo",Billetes_Brutos!D60) -> samuel.rodriguez47@correo.co | E58: =IF(Billetes_Brutos!E60="","No disponible",Billetes_Brutos!E60) -> 11/04/1992 | F58: =Billetes_Brutos!F60 -> Abonado | G58: =Billetes_Brutos!G60 -> Barranquilla | H58: =Billetes_Brutos!H60 -> Cali | I58: =Billetes_Brutos!I60 -> 19/05/2026 | J58: =Billetes_Brutos!O60 -> Primera | K58: =Billetes_Brutos!K60 -> Pagado | L58: =IF(Billetes_Brutos!L60="","Por confirmar",Billetes_Brutos!L60) -> 273400 | M58: =Billetes_Brutos!M60 -> 05/01/2026
A59: =Billetes_Brutos!A61 -> 1125 | B59: =Billetes_Brutos!B61 -> 51 | C59: =Billetes_Brutos!C61 -> Paula Gomez | D59: =IF(Billetes_Brutos!D61="","Sin correo",Billetes_Brutos!D61) -> paula.gomez51@correo.co | E59: =IF(Billetes_Brutos!E61="","No disponible",Billetes_Brutos!E61) -> 06/12/1996 | F59: =Billetes_Brutos!F61 -> Abonado | G59: =Billetes_Brutos!G61 -> Cucuta | H59: =Billetes_Brutos!H61 -> Medellin | I59: =Billetes_Brutos!I61 -> 17/01/2026 | J59: =Billetes_Brutos!O61 -> Primera | K59: =Billetes_Brutos!K61 -> Pagado | L59: =IF(Billetes_Brutos!L61="","Por confirmar",Billetes_Brutos!L61) -> 176600 | M59: =Billetes_Brutos!M61 -> 14/02/2026
A60: =Billetes_Brutos!A62 -> 1021 | B60: =Billetes_Brutos!B62 -> 60 | C60: =Billetes_Brutos!C62 -> Mateo Gomez | D60: =IF(Billetes_Brutos!D62="","Sin correo",Billetes_Brutos!D62) -> mateo.gomez60@correo.co | E60: =IF(Billetes_Brutos!E62="","No disponible",Billetes_Brutos!E62) -> 21/12/1963 | F60: =Billetes_Brutos!F62 -> Abonado | G60: =Billetes_Brutos!G62 -> Santa Marta | H60: =Billetes_Brutos!H62 -> Barranquilla | I60: =Billetes_Brutos!I62 -> 10/05/2026 | J60: =Billetes_Brutos!O62 -> Primera | K60: =Billetes_Brutos!K62 -> Pagado | L60: =IF(Billetes_Brutos!L62="","Por confirmar",Billetes_Brutos!L62) -> 63900 | M60: =Billetes_Brutos!M62 -> 02/01/2026
A61: =Billetes_Brutos!A63 -> 1103 | B61: =Billetes_Brutos!B63 -> 50 | C61: =Billetes_Brutos!C63 -> Juan Torres | D61: =IF(Billetes_Brutos!D63="","Sin correo",Billetes_Brutos!D63) -> Sin correo | E61: =IF(Billetes_Brutos!E63="","No disponible",Billetes_Brutos!E63) -> 08/01/1985 | F61: =Billetes_Brutos!F63 -> Abonado | G61: =Billetes_Brutos!G63 -> Bucaramanga | H61: =Billetes_Brutos!H63 -> Medellin | I61: =Billetes_Brutos!I63 -> 23/05/2026 | J61: =Billetes_Brutos!O63 -> Segunda | K61: =Billetes_Brutos!K63 -> Pagado | L61: =IF(Billetes_Brutos!L63="","Por confirmar",Billetes_Brutos!L63) -> 279200 | M61: =Billetes_Brutos!M63 -> 21/06/2026
A62: =Billetes_Brutos!A64 -> 1063 | B62: =Billetes_Brutos!B64 -> 31 | C62: =Billetes_Brutos!C64 -> Maria Sanchez | D62: =IF(Billetes_Brutos!D64="","Sin correo",Billetes_Brutos!D64) -> maria.sanchez31@correo.co | E62: =IF(Billetes_Brutos!E64="","No disponible",Billetes_Brutos!E64) -> 06/08/2000 | F62: =Billetes_Brutos!F64 -> Abonado | G62: =Billetes_Brutos!G64 -> Medellin | H62: =Billetes_Brutos!H64 -> Cartagena | I62: =Billetes_Brutos!I64 -> 17/04/2026 | J62: =Billetes_Brutos!O64 -> Primera | K62: =Billetes_Brutos!K64 -> Reembolsado | L62: =IF(Billetes_Brutos!L64="","Por confirmar",Billetes_Brutos!L64) -> 270700 | M62: =Billetes_Brutos!M64 -> 12/01/2026
A63: =Billetes_Brutos!A65 -> 1066 | B63: =Billetes_Brutos!B65 -> 32 | C63: =Billetes_Brutos!C65 -> Valentina Martinez | D63: =IF(Billetes_Brutos!D65="","Sin correo",Billetes_Brutos!D65) -> valentina.martinez32@correo.co | E63: =IF(Billetes_Brutos!E65="","No disponible",Billetes_Brutos!E65) -> 02/01/1964 | F63: =Billetes_Brutos!F65 -> Ocasional | G63: =Billetes_Brutos!G65 -> Medellin | H63: =Billetes_Brutos!H65 -> Santa Marta | I63: =Billetes_Brutos!I65 -> 27/04/2026 | J63: =Billetes_Brutos!O65 -> Primera | K63: =Billetes_Brutos!K65 -> Pagado | L63: =IF(Billetes_Brutos!L65="","Por confirmar",Billetes_Brutos!L65) -> 225100 | M63: =Billetes_Brutos!M65 -> 10/12/2025
A64: =Billetes_Brutos!A66 -> 1029 | B64: =Billetes_Brutos!B66 -> 22 | C64: =Billetes_Brutos!C66 -> Santiago Rodriguez | D64: =IF(Billetes_Brutos!D66="","Sin correo",Billetes_Brutos!D66) -> santiago.rodriguez22@correo.co | E64: =IF(Billetes_Brutos!E66="","No disponible",Billetes_Brutos!E66) -> 25/10/1978 | F64: =Billetes_Brutos!F66 -> Abonado | G64: =Billetes_Brutos!G66 -> Medellin | H64: =Billetes_Brutos!H66 -> Pereira | I64: =Billetes_Brutos!I66 -> 30/03/2026 | J64: =Billetes_Brutos!O66 -> Segunda | K64: =Billetes_Brutos!K66 -> Anulado | L64: =IF(Billetes_Brutos!L66="","Por confirmar",Billetes_Brutos!L66) -> 315700 | M64: =Billetes_Brutos!M66 -> 30/11/2025
A65: =Billetes_Brutos!A67 -> 1108 | B65: =Billetes_Brutos!B67 -> 58 | C65: =Billetes_Brutos!C67 -> Sebastian Gonzalez | D65: =IF(Billetes_Brutos!D67="","Sin correo",Billetes_Brutos!D67) -> sebastian.gonzalez58@correo.co | E65: =IF(Billetes_Brutos!E67="","No disponible",Billetes_Brutos!E67) -> 12/07/1994 | F65: =Billetes_Brutos!F67 -> Ocasional | G65: =Billetes_Brutos!G67 -> Cartagena | H65: =Billetes_Brutos!H67 -> Pereira | I65: =Billetes_Brutos!I67 -> 09/05/2026 | J65: =Billetes_Brutos!O67 -> Segunda | K65: =Billetes_Brutos!K67 -> Pagado | L65: =IF(Billetes_Brutos!L67="","Por confirmar",Billetes_Brutos!L67) -> 99900 | M65: =Billetes_Brutos!M67 -> 04/04/2026
A66: =Billetes_Brutos!A68 -> 1006 | B66: =Billetes_Brutos!B68 -> 42 | C66: =Billetes_Brutos!C68 -> Paula Perez | D66: =IF(Billetes_Brutos!D68="","Sin correo",Billetes_Brutos!D68) -> paula.perez42@correo.co | E66: =IF(Billetes_Brutos!E68="","No disponible",Billetes_Brutos!E68) -> 26/10/1967 | F66: =Billetes_Brutos!F68 -> Ocasional | G66: =Billetes_Brutos!G68 -> Cali | H66: =Billetes_Brutos!H68 -> Barranquilla | I66: =Billetes_Brutos!I68 -> 24/05/2026 | J66: =Billetes_Brutos!O68 -> Segunda | K66: =Billetes_Brutos!K68 -> Pagado | L66: =IF(Billetes_Brutos!L68="","Por confirmar",Billetes_Brutos!L68) -> 291900 | M66: =Billetes_Brutos!M68 -> 11/02/2026
... A99: =Billetes_Brutos!A101 -> 1040 | B99: =Billetes_Brutos!B101 -> 2 | C99: =Billetes_Brutos!C101 -> Andres Gonzalez | D99: =IF(Billetes_Brutos!D101="","Sin correo",Billetes_Brutos!D101) -> andres.gonzalez2@correo.co | E99: =IF(Billetes_Brutos!E101="","No disponible",Billetes_Brutos!E101) -> 22/10/1969 | F99: =Billetes_Brutos!F101 -> Ocasional | G99: =Billetes_Brutos!G101 -> Cali | H99: =Billetes_Brutos!H101 -> Santa Marta | I99: =Billetes_Brutos!I101 -> 07/01/2026 | J99: =Billetes_Brutos!O101 -> Segunda | K99: =Billetes_Brutos!K101 -> Pagado | L99: =IF(Billetes_Brutos!L101="","Por confirmar",Billetes_Brutos!L101) -> 68100 | M99: =Billetes_Brutos!M101 -> 18/02/2026
...
